Internal Server Error: /appPrueba/api/login
Traceback (most recent call last):
  File "C:\Users\diegu\djangoNew\tutorial-env\Lib\site-packages\django\core\handlers\exception.py", line 55, in inner
    response = get_response(request)
  File "C:\Users\diegu\djangoNew\tutorial-env\Lib\site-packages\django\utils\deprecation.py", line 131, in __call__
    response = self.process_response(request, response)
  File "C:\Users\diegu\djangoNew\tutorial-env\Lib\site-packages\django\middleware\common.py", line 108, in process_response
    return self.response_redirect_class(self.get_full_path_with_slash(request))
                                        ~~~~~~~~~~~~~~~~~~~~~~~~~~~~~^^^^^^^^^
  File "C:\Users\diegu\djangoNew\tutorial-env\Lib\site-packages\django\middleware\common.py", line 87, in get_full_path_with_slash
    raise RuntimeError(
    ...<9 lines>...
    )
RuntimeError: You called this URL via POST, but the URL doesn't end in a slash and you have APPEND_SLASH set. Django can't redirect to the slash URL while maintaining POST data. Change your form to point to 127.0.0.1:8000/appPrueba/api/login/ (note the trailing slash), or set APPEND_SLASH=False in your Django settings.
"POST /appPrueba/api/login HTTP/1.1" 500 70724
Internal Server Error: /appPrueba/api/login/
Traceback (most recent call last):
  File "C:\Users\diegu\djangoNew\tutorial-env\Lib\site-packages\django\core\handlers\exception.py", line 55, in inner
    response = get_response(request)
  File "C:\Users\diegu\djangoNew\tutorial-env\Lib\site-packages\django\core\handlers\base.py", line 197, in _get_response
    response = wrapped_callback(request, *callback_args, **callback_kwargs)
  File "C:\Users\diegu\djangoNew\tutorial-env\Lib\site-packages\django\views\decorators\csrf.py", line 65, in _view_wrapper
    return view_func(request, *args, **kwargs)
  File "C:\Users\diegu\djangoNew\tutorial-env\Lib\site-packages\django\views\generic\base.py", line 104, in view
    return self.dispatch(request, *args, **kwargs)
           ~~~~~~~~~~~~~^^^^^^^^^^^^^^^^^^^^^^^^^^
  File "C:\Users\diegu\djangoNew\tutorial-env\Lib\site-packages\rest_framework\views.py", line 509, in dispatch
    response = self.handle_exception(exc)
  File "C:\Users\diegu\djangoNew\tutorial-env\Lib\site-packages\rest_framework\views.py", line 469, in handle_exception
    self.raise_uncaught_exception(exc)
    ~~~~~~~~~~~~~~~~~~~~~~~~~~~~~^^^^^
  File "C:\Users\diegu\djangoNew\tutorial-env\Lib\site-packages\rest_framework\views.py", line 480, in raise_uncaught_exception
    raise exc
  File "C:\Users\diegu\djangoNew\tutorial-env\Lib\site-packages\rest_framework\views.py", line 497, in dispatch
    self.initial(request, *args, **kwargs)
    ~~~~~~~~~~~~^^^^^^^^^^^^^^^^^^^^^^^^^^
  File "C:\Users\diegu\djangoNew\tutorial-env\Lib\site-packages\rest_framework\views.py", line 415, in initial
    self.check_permissions(request)
    ~~~~~~~~~~~~~~~~~~~~~~^^^^^^^^^
  File "C:\Users\diegu\djangoNew\tutorial-env\Lib\site-packages\rest_framework\views.py", line 332, in check_permissions
    if not permission.has_permission(request, self):
           ^^^^^^^^^^^^^^^^^^^^^^^^^
AttributeError: 'JWTAuthentication' object has no attribute 'has_permission'
"POST /appPrueba/api/login/ HTTP/1.1" 500 97574
Internal Server Error: /appPrueba/api/login/
Traceback (most recent call last):
  File "C:\Users\diegu\djangoNew\tutorial-env\Lib\site-packages\django\core\handlers\exception.py", line 55, in inner
    response = get_response(request)
  File "C:\Users\diegu\djangoNew\tutorial-env\Lib\site-packages\django\core\handlers\base.py", line 197, in _get_response
    response = wrapped_callback(request, *callback_args, **callback_kwargs)
  File "C:\Users\diegu\djangoNew\tutorial-env\Lib\site-packages\django\views\decorators\csrf.py", line 65, in _view_wrapper
    return view_func(request, *args, **kwargs)
  File "C:\Users\diegu\djangoNew\tutorial-env\Lib\site-packages\django\views\generic\base.py", line 104, in view
    return self.dispatch(request, *args, **kwargs)
           ~~~~~~~~~~~~~^^^^^^^^^^^^^^^^^^^^^^^^^^
  File "C:\Users\diegu\djangoNew\tutorial-env\Lib\site-packages\rest_framework\views.py", line 509, in dispatch
    response = self.handle_exception(exc)
  File "C:\Users\diegu\djangoNew\tutorial-env\Lib\site-packages\rest_framework\views.py", line 469, in handle_exception
    self.raise_uncaught_exception(exc)
    ~~~~~~~~~~~~~~~~~~~~~~~~~~~~~^^^^^
  File "C:\Users\diegu\djangoNew\tutorial-env\Lib\site-packages\rest_framework\views.py", line 480, in raise_uncaught_exception
    raise exc
  File "C:\Users\diegu\djangoNew\tutorial-env\Lib\site-packages\rest_framework\views.py", line 497, in dispatch
    self.initial(request, *args, **kwargs)
    ~~~~~~~~~~~~^^^^^^^^^^^^^^^^^^^^^^^^^^
  File "C:\Users\diegu\djangoNew\tutorial-env\Lib\site-packages\rest_framework\views.py", line 415, in initial
    self.check_permissions(request)
    ~~~~~~~~~~~~~~~~~~~~~~^^^^^^^^^
  File "C:\Users\diegu\djangoNew\tutorial-env\Lib\site-packages\rest_framework\views.py", line 332, in check_permissions
    if not permission.has_permission(request, self):
           ^^^^^^^^^^^^^^^^^^^^^^^^^
AttributeError: 'JWTAuthentication' object has no attribute 'has_permission'
"POST /appPrueba/api/login/ HTTP/1.1" 500 97585
Internal Server Error: /appPrueba/api/login/
Traceback (most recent call last):
  File "C:\Users\diegu\djangoNew\tutorial-env\Lib\site-packages\django\core\handlers\exception.py", line 55, in inner
    response = get_response(request)
  File "C:\Users\diegu\djangoNew\tutorial-env\Lib\site-packages\django\core\handlers\base.py", line 197, in _get_response
    response = wrapped_callback(request, *callback_args, **callback_kwargs)
  File "C:\Users\diegu\djangoNew\tutorial-env\Lib\site-packages\django\views\decorators\csrf.py", line 65, in _view_wrapper
    return view_func(request, *args, **kwargs)
  File "C:\Users\diegu\djangoNew\tutorial-env\Lib\site-packages\django\views\generic\base.py", line 104, in view
    return self.dispatch(request, *args, **kwargs)
           ~~~~~~~~~~~~~^^^^^^^^^^^^^^^^^^^^^^^^^^
  File "C:\Users\diegu\djangoNew\tutorial-env\Lib\site-packages\rest_framework\views.py", line 509, in dispatch
    response = self.handle_exception(exc)
  File "C:\Users\diegu\djangoNew\tutorial-env\Lib\site-packages\rest_framework\views.py", line 469, in handle_exception
    self.raise_uncaught_exception(exc)
    ~~~~~~~~~~~~~~~~~~~~~~~~~~~~~^^^^^
  File "C:\Users\diegu\djangoNew\tutorial-env\Lib\site-packages\rest_framework\views.py", line 480, in raise_uncaught_exception
    raise exc
  File "C:\Users\diegu\djangoNew\tutorial-env\Lib\site-packages\rest_framework\views.py", line 497, in dispatch
    self.initial(request, *args, **kwargs)
    ~~~~~~~~~~~~^^^^^^^^^^^^^^^^^^^^^^^^^^
  File "C:\Users\diegu\djangoNew\tutorial-env\Lib\site-packages\rest_framework\views.py", line 415, in initial
    self.check_permissions(request)
    ~~~~~~~~~~~~~~~~~~~~~~^^^^^^^^^
  File "C:\Users\diegu\djangoNew\tutorial-env\Lib\site-packages\rest_framework\views.py", line 332, in check_permissions
    if not permission.has_permission(request, self):
           ^^^^^^^^^^^^^^^^^^^^^^^^^
AttributeError: 'JWTAuthentication' object has no attribute 'has_permission'
"POST /appPrueba/api/login/ HTTP/1.1" 500 97034
Internal Server Error: /appPrueba/api/login/
Traceback (most recent call last):
  File "C:\Users\diegu\djangoNew\tutorial-env\Lib\site-packages\django\core\handlers\exception.py", line 55, in inner
    response = get_response(request)
  File "C:\Users\diegu\djangoNew\tutorial-env\Lib\site-packages\django\core\handlers\base.py", line 197, in _get_response
    response = wrapped_callback(request, *callback_args, **callback_kwargs)
  File "C:\Users\diegu\djangoNew\tutorial-env\Lib\site-packages\django\views\decorators\csrf.py", line 65, in _view_wrapper
    return view_func(request, *args, **kwargs)
  File "C:\Users\diegu\djangoNew\tutorial-env\Lib\site-packages\django\views\generic\base.py", line 104, in view
    return self.dispatch(request, *args, **kwargs)
           ~~~~~~~~~~~~~^^^^^^^^^^^^^^^^^^^^^^^^^^
  File "C:\Users\diegu\djangoNew\tutorial-env\Lib\site-packages\rest_framework\views.py", line 509, in dispatch
    response = self.handle_exception(exc)
  File "C:\Users\diegu\djangoNew\tutorial-env\Lib\site-packages\rest_framework\views.py", line 469, in handle_exception
    self.raise_uncaught_exception(exc)
    ~~~~~~~~~~~~~~~~~~~~~~~~~~~~~^^^^^
  File "C:\Users\diegu\djangoNew\tutorial-env\Lib\site-packages\rest_framework\views.py", line 480, in raise_uncaught_exception
    raise exc
  File "C:\Users\diegu\djangoNew\tutorial-env\Lib\site-packages\rest_framework\views.py", line 497, in dispatch
    self.initial(request, *args, **kwargs)
    ~~~~~~~~~~~~^^^^^^^^^^^^^^^^^^^^^^^^^^
  File "C:\Users\diegu\djangoNew\tutorial-env\Lib\site-packages\rest_framework\views.py", line 415, in initial
    self.check_permissions(request)
    ~~~~~~~~~~~~~~~~~~~~~~^^^^^^^^^
  File "C:\Users\diegu\djangoNew\tutorial-env\Lib\site-packages\rest_framework\views.py", line 332, in check_permissions
    if not permission.has_permission(request, self):
           ^^^^^^^^^^^^^^^^^^^^^^^^^
AttributeError: 'JWTAuthentication' object has no attribute 'has_permission'
"POST /appPrueba/api/login/ HTTP/1.1" 500 96925
